<?xml version="1.0" ?>
<!-- =================================================================================== -->
<!-- |    This document was autogenerated by xacro from /home/ubuntu/final_ws/src/da_vincibot_description/urdf/da_vincibot.xacro | -->
<!-- |    EDITING THIS FILE BY HAND IS NOT RECOMMENDED                                 | -->
<!-- =================================================================================== -->
<robot name="da_vincibot">
    <material name="silver">
        <color rgba="0.700 0.700 0.700 1.000" />
    </material>
    <transmission name="joint1_shoulder_tran">
        <type>transmission_interface/SimpleTransmission</type>
        <joint name="joint1_shoulder">
            <hardwareInterface>hardware_interface/EffortJointInterface</hardwareInterface>
        </joint>
        <actuator name="joint1_shoulder_actr">
            <hardwareInterface>hardware_interface/EffortJointInterface</hardwareInterface>
            <mechanicalReduction>1</mechanicalReduction>
        </actuator>
    </transmission>
    <transmission name="joint2_forearm_tran">
        <type>transmission_interface/SimpleTransmission</type>
        <joint name="joint2_forearm">
            <hardwareInterface>hardware_interface/EffortJointInterface</hardwareInterface>
        </joint>
        <actuator name="joint2_forearm_actr">
            <hardwareInterface>hardware_interface/EffortJointInterface</hardwareInterface>
            <mechanicalReduction>1</mechanicalReduction>
        </actuator>
    </transmission>
    <transmission name="joint3_hand_tran">
        <type>transmission_interface/SimpleTransmission</type>
        <joint name="joint3_hand">
            <hardwareInterface>hardware_interface/EffortJointInterface</hardwareInterface>
        </joint>
        <actuator name="joint3_hand_actr">
            <hardwareInterface>hardware_interface/EffortJointInterface</hardwareInterface>
            <mechanicalReduction>1</mechanicalReduction>
        </actuator>
    </transmission>
    <transmission name="joint4_handyaw_tran">
        <type>transmission_interface/SimpleTransmission</type>
        <joint name="joint4_handyaw">
            <hardwareInterface>hardware_interface/EffortJointInterface</hardwareInterface>
        </joint>
        <actuator name="joint4_handyaw_actr">
            <hardwareInterface>hardware_interface/EffortJointInterface</hardwareInterface>
            <mechanicalReduction>1</mechanicalReduction>
        </actuator>
    </transmission>
    <transmission name="joint5_end_tran">
        <type>transmission_interface/SimpleTransmission</type>
        <joint name="joint5_end">
            <hardwareInterface>hardware_interface/EffortJointInterface</hardwareInterface>
        </joint>
        <actuator name="joint5_end_actr">
            <hardwareInterface>hardware_interface/EffortJointInterface</hardwareInterface>
            <mechanicalReduction>1</mechanicalReduction>
        </actuator>
    </transmission>
    <gazebo>
        <plugin filename="libgazebo_ros_control.so" name="control" />
        <plugin name="gazebo_ros_control">
            <robotNamespace>/</robotNamespace>
        </plugin>
    </gazebo>
    <gazebo reference="base_link">
        <material>Gazebo/Silver</material>
        <mu1>0.2</mu1>
        <mu2>0.2</mu2>
        <selfCollide>true</selfCollide>
        <gravity>true</gravity>
    </gazebo>
    <gazebo reference="foundation_base_1">
        <material>Gazebo/Silver</material>
        <mu1>0.2</mu1>
        <mu2>0.2</mu2>
        <selfCollide>true</selfCollide>
    </gazebo>
    <gazebo reference="shoulder_1">
        <material>Gazebo/Silver</material>
        <mu1>0.2</mu1>
        <mu2>0.2</mu2>
        <selfCollide>true</selfCollide>
    </gazebo>
    <gazebo reference="forearm_1">
        <material>Gazebo/Silver</material>
        <mu1>0.2</mu1>
        <mu2>0.2</mu2>
        <selfCollide>true</selfCollide>
    </gazebo>
    <gazebo reference="hand_1">
        <material>Gazebo/Silver</material>
        <mu1>0.2</mu1>
        <mu2>0.2</mu2>
        <selfCollide>true</selfCollide>
    </gazebo>
    <gazebo reference="hand_yaw_1">
        <material>Gazebo/Silver</material>
        <mu1>0.2</mu1>
        <mu2>0.2</mu2>
        <selfCollide>true</selfCollide>
    </gazebo>
    <gazebo reference="end_effector_1">
        <material>Gazebo/Silver</material>
        <mu1>0.2</mu1>
        <mu2>0.2</mu2>
        <selfCollide>true</selfCollide>
    </gazebo>
    <gazebo reference="end_1">
        <material>Gazebo/Silver</material>
        <mu1>0.2</mu1>
        <mu2>0.2</mu2>
        <selfCollide>true</selfCollide>
    </gazebo>
    <gazebo reference="arducam_v1_1">
        <material>Gazebo/Silver</material>
        <mu1>0.2</mu1>
        <mu2>0.2</mu2>
        <selfCollide>true</selfCollide>
    </gazebo>
    <link name="dummy" />
    <joint name="dummy_joint" type="fixed">
        <parent link="dummy" />
        <child link="base_link" />
    </joint>
    <link name="base_link">
        <inertial>
            <origin rpy="0 0 0" xyz="-0.013780680089318771 0.29685490907620005 0.1796297335203369" />
            <mass value="35.9352" />
            <inertia ixx="3.30678" ixy="0.006439" ixz="0.135672" iyy="3.232001" iyz="-0.268124" izz="3.200963" />
        </inertial>
        <visual>
            <origin rpy="0 0 0" xyz="0 0 0" />
            <geometry>
                <mesh filename="package://da_vincibot_description/meshes/base_link.stl" scale="0.001 0.001 0.001" />
            </geometry>
            <material name="silver" />
        </visual>
        <collision>
            <origin rpy="0 0 0" xyz="0 0 0" />
            <geometry>
                <mesh filename="package://da_vincibot_description/meshes/base_link.stl" scale="0.001 0.001 0.001" />
            </geometry>
        </collision>
    </link>
    <link name="foundation_base_1">
        <inertial>
            <origin rpy="0 0 0" xyz="0.009586868297954514 -0.04216855497473093 0.47160422842803157" />
            <mass value="118.48330496102017" />
            <inertia ixx="13.892787" ixy="-0.0" ixz="0.0" iyy="13.72668" iyz="-0.004549" izz="10.409594" />
        </inertial>
        <visual>
            <origin rpy="0 0 0" xyz="0.019174 0.220837 -0.01" />
            <geometry>
                <mesh filename="package://da_vincibot_description/meshes/foundation_base_1.stl" scale="0.001 0.001 0.001" />
            </geometry>
            <material name="silver" />
        </visual>
        <collision>
            <origin rpy="0 0 0" xyz="0.019174 0.220837 -0.01" />
            <geometry>
                <mesh filename="package://da_vincibot_description/meshes/foundation_base_1.stl" scale="0.001 0.001 0.001" />
            </geometry>
        </collision>
    </link>
    <link name="shoulder_1">
        <inertial>
            <origin rpy="0 0 0" xyz="0.025755144680148674 -0.03339939669169957 0.036650849280556064" />
            <mass value="12.004176876206436" />
            <inertia ixx="0.118408" ixy="-0.010234" ixz="-0.003498" iyy="0.123788" iyz="0.004536" izz="0.147792" />
        </inertial>
        <visual>
            <origin rpy="0 0 0" xyz="0.009587 0.110419 -0.661" />
            <geometry>
                <mesh filename="package://da_vincibot_description/meshes/shoulder_1.stl" scale="0.001 0.001 0.001" />
            </geometry>
            <material name="silver" />
        </visual>
        <collision>
            <origin rpy="0 0 0" xyz="0.009587 0.110419 -0.661" />
            <geometry>
                <mesh filename="package://da_vincibot_description/meshes/shoulder_1.stl" scale="0.001 0.001 0.001" />
            </geometry>
        </collision>
    </link>
    <link name="forearm_1">
        <inertial>
            <origin rpy="0 0 0" xyz="0.07100778254631218 0.05529958973514852 0.04756542152195098" />
            <mass value="3.191348499369228" />
            <inertia ixx="0.110231" ixy="-0.013234" ixz="-5.6e-05" iyy="0.117188" iyz="7.3e-05" izz="0.030159" />
        </inertial>
        <visual>
            <origin rpy="0 0 0" xyz="0.080858 0.165377 -0.8545" />
            <geometry>
                <mesh filename="package://da_vincibot_description/meshes/forearm_1.stl" scale="0.001 0.001 0.001" />
            </geometry>
            <material name="silver" />
        </visual>
        <collision>
            <origin rpy="0 0 0" xyz="0.080858 0.165377 -0.8545" />
            <geometry>
                <mesh filename="package://da_vincibot_description/meshes/forearm_1.stl" scale="0.001 0.001 0.001" />
            </geometry>
        </collision>
    </link>
    <link name="hand_1">
        <inertial>
            <origin rpy="0 0 0" xyz="0.06847215720316376 -0.018647155150894656 0.05483920948448584" />
            <mass value="1.0662125112424885" />
            <inertia ixx="0.019715" ixy="0.006528" ixz="-0.007063" iyy="0.016283" iyz="0.00916" izz="0.016644" />
        </inertial>
        <visual>
            <origin rpy="0 0 0" xyz="0.041263 0.134845 -1.2745" />
            <geometry>
                <mesh filename="package://da_vincibot_description/meshes/hand_1.stl" scale="0.001 0.001 0.001" />
            </geometry>
            <material name="silver" />
        </visual>
        <collision>
            <origin rpy="0 0 0" xyz="0.041263 0.134845 -1.2745" />
            <geometry>
                <mesh filename="package://da_vincibot_description/meshes/hand_1.stl" scale="0.001 0.001 0.001" />
            </geometry>
        </collision>
    </link>
    <link name="hand_yaw_1">
        <inertial>
            <origin rpy="0 0 0" xyz="0.014374671356375074 -0.018641065652960254 0.019752517482224397" />
            <mass value="0.19229044235074944" />
            <inertia ixx="0.00039" ixy="8.1e-05" ixz="8.9e-05" iyy="0.000348" iyz="-0.000115" izz="0.000235" />
        </inertial>
        <visual>
            <origin rpy="0 0 0" xyz="-0.175095 0.345273 -1.525187" />
            <geometry>
                <mesh filename="package://da_vincibot_description/meshes/hand_yaw_1.stl" scale="0.001 0.001 0.001" />
            </geometry>
            <material name="silver" />
        </visual>
        <collision>
            <origin rpy="0 0 0" xyz="-0.175095 0.345273 -1.525187" />
            <geometry>
                <mesh filename="package://da_vincibot_description/meshes/hand_yaw_1.stl" scale="0.001 0.001 0.001" />
            </geometry>
        </collision>
    </link>
    <link name="end_effector_1">
        <inertial>
            <origin rpy="0 0 0" xyz="-0.13513566300895505 -0.08879838085005426 0.024916464751506773" />
            <mass value="0.49047145154717503" />
            <inertia ixx="0.000952" ixy="-0.00082" ixz="3.9e-05" iyy="0.001273" iyz="2.2e-05" izz="0.001944" />
        </inertial>
        <visual>
            <origin rpy="0 0 0" xyz="-0.211088 0.391885 -1.541968" />
            <geometry>
                <mesh filename="package://da_vincibot_description/meshes/end_effector_1.stl" scale="0.001 0.001 0.001" />
            </geometry>
            <material name="silver" />
        </visual>
        <collision>
            <origin rpy="0 0 0" xyz="-0.211088 0.391885 -1.541968" />
            <geometry>
                <mesh filename="package://da_vincibot_description/meshes/end_effector_1.stl" scale="0.001 0.001 0.001" />
            </geometry>
        </collision>
    </link>
    <link name="end_1">
        <inertial>
            <origin rpy="0 0 0" xyz="-3.878603250144497e-05 -3.171408265412179e-05 1.5213265980307256e-06" />
            <mass value="0.00014967725498964528" />
            <inertia ixx="0.0" ixy="0.0" ixz="-0.0" iyy="0.0" iyz="-0.0" izz="0.0" />
        </inertial>
        <visual>
            <origin rpy="0 0 0" xyz="-0.016138 0.531822 -1.567211" />
            <geometry>
                <mesh filename="package://da_vincibot_description/meshes/end_1.stl" scale="0.001 0.001 0.001" />
            </geometry>
            <material name="silver" />
        </visual>
        <collision>
            <origin rpy="0 0 0" xyz="-0.016138 0.531822 -1.567211" />
            <geometry>
                <mesh filename="package://da_vincibot_description/meshes/end_1.stl" scale="0.001 0.001 0.001" />
            </geometry>
        </collision>
    </link>
    <link name="arducam_v1_1">
        <inertial>
            <origin rpy="0 0 0" xyz="-0.020000131702510495 4.1679008455641764e-07 -0.0021523835366652477" />
            <mass value="0.0047707963267949235" />
            <inertia ixx="0.0" ixy="0.0" ixz="0.0" iyy="0.0" iyz="0.0" izz="1e-06" />
        </inertial>
        <visual>
            <origin rpy="0 0 0" xyz="-0.010413 -0.339581 -1.41" />
            <geometry>
                <mesh filename="package://da_vincibot_description/meshes/arducam_v1_1.stl" scale="0.001 0.001 0.001" />
            </geometry>
            <material name="silver" />
        </visual>
        <collision>
            <origin rpy="0 0 0" xyz="-0.010413 -0.339581 -1.41" />
            <geometry>
                <mesh filename="package://da_vincibot_description/meshes/arducam_v1_1.stl" scale="0.001 0.001 0.001" />
            </geometry>
        </collision>
    </link>
    <joint name="rigid2" type="fixed">
        <origin rpy="0 0 0" xyz="-0.019174 -0.220837 0.01" />
        <parent link="base_link" />
        <child link="foundation_base_1" />
    </joint>
    <joint name="joint1_shoulder" type="revolute">
        <origin rpy="0 0 0" xyz="0.009587 0.110418 0.651" />
        <parent link="foundation_base_1" />
        <child link="shoulder_1" />
        <axis xyz="0.0 -0.0 1.0" />
        <limit effort="100" lower="0.0" upper="4.712389" velocity="100" />
    </joint>
    <joint name="joint2_forearm" type="revolute">
        <origin rpy="0 0 0" xyz="-0.071271 -0.054958 0.1935" />
        <parent link="shoulder_1" />
        <child link="forearm_1" />
        <axis xyz="0.7919 0.61065 0.0" />
        <limit effort="100" lower="0.0" upper="2.094395" velocity="100" />
    </joint>
    <joint name="joint3_hand" type="revolute">
        <origin rpy="0 0 0" xyz="0.039595 0.030532 0.42" />
        <parent link="forearm_1" />
        <child link="hand_1" />
        <axis xyz="0.7919 0.61065 0.0" />
        <limit effort="100" lower="0.0" upper="1.396263" velocity="100" />
    </joint>
    <joint name="joint4_handyaw" type="revolute">
        <origin rpy="0 0 0" xyz="0.216358 -0.210428 0.250687" />
        <parent link="hand_1" />
        <child link="hand_yaw_1" />
        <axis xyz="-0.467785 0.606631 -0.642788" />
        <limit effort="100" lower="0.0" upper="3.141593" velocity="100" />
    </joint>
    <joint name="joint5_end" type="revolute">
        <origin rpy="0 0 0" xyz="0.035993 -0.046612 0.016781" />
        <parent link="hand_yaw_1" />
        <child link="end_effector_1" />
        <axis xyz="-0.393746 0.508076 0.766044" />
        <limit effort="100" lower="0.0" upper="3.141593" velocity="100" />
    </joint>
    <joint name="end_rigid" type="fixed">
        <origin rpy="0 0 0" xyz="-0.19495 -0.139937 0.025243" />
        <parent link="end_effector_1" />
        <child link="end_1" />
    </joint>
    <joint name="rigid1" type="fixed">
        <origin rpy="0 0 0" xyz="0.010413 0.339581 1.41" />
        <parent link="base_link" />
        <child link="arducam_v1_1" />
    </joint>
</robot>

