<?xml version="1.0" ?>
<!-- =================================================================================== -->
<!-- |    This document was autogenerated by xacro from /home/ubuntu/flipkart_ws/src/robotic_description/urdf/robotic.xacro | -->
<!-- |    EDITING THIS FILE BY HAND IS NOT RECOMMENDED                                 | -->
<!-- =================================================================================== -->
<robot name="robotic">
    <material name="silver">
        <color rgba="0.700 0.700 0.700 1.000" />
    </material>
    <link name="dummy" />
    <joint name="dummy_joint" type="fixed">
        <parent link="dummy" />
        <child link="base_link" />
    </joint>
    <link name="base_link">
        <inertial>
            <origin rpy="0 0 0" xyz="0.1351124948669782 -0.42068294522758753 0.2341784066776522" />
            <mass value="777.7493009183014" />
            <inertia ixx="135.532532" ixy="3.178232" ixz="0.036953" iyy="109.450515" iyz="3.236105" izz="135.60657" />
        </inertial>
        <visual>
            <origin rpy="0 0 0" xyz="0 0 0.21" />
            <geometry>
                <mesh filename="package://robotic_description/mesh/base_link.stl" scale="0.001 0.001 0.001" />
            </geometry>
            <material name="silver" />
        </visual>
        <collision>
            <origin rpy="0 0 0" xyz="0 0 0.21" />
            <geometry>
                <mesh filename="package://robotic_description/mesh/base_link.stl" scale="0.001 0.001 0.001" />
            </geometry>
        </collision>
    </link>
    <link name="arm_1">
        <inertial>
            <origin rpy="0 0 0" xyz="-0.025327304313694593 1.83695537267492e-07 0.15747269850712742" />
            <mass value="3.4188971292058414" />
            <inertia ixx="0.018482" ixy="0.0" ixz="0.003682" iyy="0.031796" iyz="-0.0" izz="0.018214" />
        </inertial>
        <visual>
            <origin rpy="0 0 0" xyz="-0.144802 0.073927 -0.644082" />
            <geometry>
                <mesh filename="package://robotic_description/mesh/arm_1.stl" scale="0.001 0.001 0.001" />
            </geometry>
            <material name="silver" />
        </visual>
        <collision>
            <origin rpy="0 0 0" xyz="-0.144802 0.073927 -0.644082" />
            <geometry>
                <mesh filename="package://robotic_description/mesh/arm_1.stl" scale="0.001 0.001 0.001" />
            </geometry>
        </collision>
    </link>
    <link name="end_1">
        <inertial>
            <origin rpy="0 0 0" xyz="-0.07035008395779202 2.005916116543105e-07 -0.05982240354354046" />
            <mass value="0.28541935964994736" />
            <inertia ixx="0.001098" ixy="0.0" ixz="-4e-05" iyy="0.001844" iyz="0.0" izz="0.001696" />
        </inertial>
        <visual>
            <origin rpy="0 0 0" xyz="-0.219802 -0.616073 -0.154082" />
            <geometry>
                <mesh filename="package://vinci_bot_description/meshes/end_1.stl" scale="0.001 0.001 0.001" />
            </geometry>
            <material name="silver" />
        </visual>
        <collision>
            <origin rpy="0 0 0" xyz="-0.219802 -0.616073 -0.154082" />
            <geometry>
                <mesh filename="package://vinci_bot_description/meshes/end_1.stl" scale="0.001 0.001 0.001" />
            </geometry>
        </collision>
    </link>
    <link name="hand_1">
        <inertial>
            <origin rpy="0 0 0" xyz="0.06495053474908702 2.417388758058081e-07 -0.3250315992683306" />
            <mass value="8.616717936895942" />
            <inertia ixx="0.616811" ixy="-0.0" ixz="0.028145" iyy="0.63362" iyz="0.0" izz="0.029126" />
        </inertial>
        <visual>
            <origin rpy="0 0 0" xyz="-0.069802 -0.616073 -0.844082" />
            <geometry>
                <mesh filename="package://vinci_bot_description/meshes/hand_1.stl" scale="0.001 0.001 0.001" />
            </geometry>
            <material name="silver" />
        </visual>
        <collision>
            <origin rpy="0 0 0" xyz="-0.069802 -0.616073 -0.844082" />
            <geometry>
                <mesh filename="package://vinci_bot_description/meshes/hand_1.stl" scale="0.001 0.001 0.001" />
            </geometry>
        </collision>
    </link>
    <link name="forearm_1">
        <inertial>
            <origin rpy="0 0 0" xyz="-0.07500037778459376 0.3450001901687444 6.919054307275019e-08" />
            <mass value="6.806430258689737" />
            <inertia ixx="0.40369" ixy="-0.0" ixz="-0.0" iyy="0.012647" iyz="0.0" izz="0.405107" />
        </inertial>
        <visual>
            <origin rpy="0 0 0" xyz="-0.069802 0.073927 -0.844082" />
            <geometry>
                <mesh filename="package://vinci_bot_description/meshes/forearm_1.stl" scale="0.001 0.001 0.001" />
            </geometry>
            <material name="silver" />
        </visual>
        <collision>
            <origin rpy="0 0 0" xyz="-0.069802 0.073927 -0.844082" />
            <geometry>
                <mesh filename="package://vinci_bot_description/meshes/forearm_1.stl" scale="0.001 0.001 0.001" />
            </geometry>
        </collision>
    </link>
    <joint name="joint4" type="continuous">
        <origin rpy="0 0 0" xyz="0.144802 -0.073927 0.854082" />
        <parent link="base_link" />
        <child link="arm_1" />
        <axis xyz="0.0 0.0 1.0" />
        <!-- <limit effort="500" lower="-3.14" upper="3.14" velocity="7.5" /> -->
    </joint>
    <transmission name="joint4_tran">
        <type>transmission_interface/SimpleTransmission</type>
        <joint name="joint4">
            <hardwareInterface>hardware_interface/EffortJointInterface</hardwareInterface>
        </joint>
        <actuator name="joint4_actr">
            <hardwareInterface>hardware_interface/EffortJointInterface</hardwareInterface>
            <mechanicalReduction>1</mechanicalReduction>
        </actuator>
    </transmission>
    <joint name="joint1" type="continuous">
        <origin rpy="0 0 0" xyz="0.15 0.0 -0.69" />
        <parent link="hand_1" />
        <child link="end_1" />
        <axis xyz="-1.0 -0.0 -0.0" />
        <!-- <limit effort="50" lower="-3.14" upper="3.14" velocity="7.5" /> -->
    </joint>
    <transmission name="joint1_tran">
        <type>transmission_interface/SimpleTransmission</type>
        <joint name="joint1">
            <hardwareInterface>hardware_interface/EffortJointInterface</hardwareInterface>
        </joint>
        <actuator name="joint1_actr">
            <hardwareInterface>hardware_interface/EffortJointInterface</hardwareInterface>
            <mechanicalReduction>1</mechanicalReduction>
        </actuator>
    </transmission>
    <joint name="joint2" type="continuous">
        <origin rpy="0 0 0" xyz="0.0 0.69 0.0" />
        <parent link="forearm_1" />
        <child link="hand_1" />
        <axis xyz="1.0 0.0 0.0" />
        <!-- <limit effort="50" lower="-3.14" upper="3.14" velocity="7.5" /> -->
    </joint>
    <transmission name="joint2_tran">
        <type>transmission_interface/SimpleTransmission</type>
        <joint name="joint2">
            <hardwareInterface>hardware_interface/EffortJointInterface</hardwareInterface>
        </joint>
        <actuator name="joint2_actr">
            <hardwareInterface>hardware_interface/EffortJointInterface</hardwareInterface>
            <mechanicalReduction>1</mechanicalReduction>
        </actuator>
    </transmission>
    <joint name="joint3" type="continuous">
        <origin rpy="0 0 0" xyz="-0.075 0.0 0.2" />
        <parent link="arm_1" />
        <child link="forearm_1" />
        <axis xyz="1.0 0.0 0.0" />
        <!-- <limit effort="500" lower="-3.14" upper="3.14" velocity="7.5" /> -->
    </joint>
    <transmission name="joint3_tran">
        <type>transmission_interface/SimpleTransmission</type>
        <joint name="joint3">
            <hardwareInterface>hardware_interface/EffortJointInterface</hardwareInterface>
        </joint>
        <actuator name="joint3_actr">
            <hardwareInterface>hardware_interface/EffortJointInterface</hardwareInterface>
            <mechanicalReduction>1</mechanicalReduction>
        </actuator>
    </transmission>
    <!-- <gazebo>
    <plugin name="gazebo_ros_control" filename="libgazebo_ros_control.so">
    </plugin>
</gazebo> -->
    <gazebo>
        <plugin filename="libgazebo_ros_control.so" name="gazebo_ros_control">
            <!-- <robotNamespace>/robotic</robotNamespace>  -->
            <robotNamespace>/</robotNamespace>
        </plugin>
    </gazebo>
</robot>

