<?xml version="1.0" ?>
<robot name="da_vincibot" xmlns:xacro="http://www.ros.org/wiki/xacro">

<xacro:include filename="$(find da_vincibot_description)/urdf/materials.xacro" />
<xacro:include filename="$(find da_vincibot_description)/urdf/da_vincibot.trans" />
<xacro:include filename="$(find da_vincibot_description)/urdf/da_vincibot.gazebo" />

<link name="dummy">
   </link>
<joint name="dummy_joint" type="fixed">
     <parent link="dummy"/>
     <child link="base_link"/>
</joint>

<link name="base_link">
  <inertial>
    <origin xyz="-0.013780680089318771 0.29685490907620005 0.1796297335203369" rpy="0 0 0"/>
    <mass value="35.9352"/>
    <inertia ixx="3.30678" iyy="3.232001" izz="3.200963" ixy="0.006439" iyz="-0.268124" ixz="0.135672"/>
  </inertial>
  <visual>
    <origin xyz="0 0 0" rpy="0 0 0"/>
    <geometry>
      <mesh filename="package://da_vincibot_description/meshes/base_link.stl" scale="0.001 0.001 0.001"/>
    </geometry>
    <material name="silver"/>
  </visual>
  <collision>
    <origin xyz="0 0 0" rpy="0 0 0"/>
    <geometry>
      <mesh filename="package://da_vincibot_description/meshes/base_link.stl" scale="0.001 0.001 0.001"/>
    </geometry>
  </collision>
</link>

<link name="foundation_base_1">
  <inertial>
    <origin xyz="0.009586868297954514 -0.04216855497473093 0.47160422842803157" rpy="0 0 0"/>
    <mass value="118.48330496102017"/>
    <inertia ixx="13.892787" iyy="13.72668" izz="10.409594" ixy="-0.0" iyz="-0.004549" ixz="0.0"/>
  </inertial>
  <visual>
    <origin xyz="0.019174 0.220837 -0.01" rpy="0 0 0"/>
    <geometry>
      <mesh filename="package://da_vincibot_description/meshes/foundation_base_1.stl" scale="0.001 0.001 0.001"/>
    </geometry>
    <material name="silver"/>
  </visual>
  <collision>
    <origin xyz="0.019174 0.220837 -0.01" rpy="0 0 0"/>
    <geometry>
      <mesh filename="package://da_vincibot_description/meshes/foundation_base_1.stl" scale="0.001 0.001 0.001"/>
    </geometry>
  </collision>
</link>

<link name="shoulder_1">
  <inertial>
    <origin xyz="0.025755144680148674 -0.03339939669169957 0.036650849280556064" rpy="0 0 0"/>
    <mass value="12.004176876206436"/>
    <inertia ixx="0.118408" iyy="0.123788" izz="0.147792" ixy="-0.010234" iyz="0.004536" ixz="-0.003498"/>
  </inertial>
  <visual>
    <origin xyz="0.009587 0.110419 -0.661" rpy="0 0 0"/>
    <geometry>
      <mesh filename="package://da_vincibot_description/meshes/shoulder_1.stl" scale="0.001 0.001 0.001"/>
    </geometry>
    <material name="silver"/>
  </visual>
  <collision>
    <origin xyz="0.009587 0.110419 -0.661" rpy="0 0 0"/>
    <geometry>
      <mesh filename="package://da_vincibot_description/meshes/shoulder_1.stl" scale="0.001 0.001 0.001"/>
    </geometry>
  </collision>
</link>

<link name="forearm_1">
  <inertial>
    <origin xyz="0.07100778254631218 0.05529958973514852 0.04756542152195098" rpy="0 0 0"/>
    <mass value="3.191348499369228"/>
    <inertia ixx="0.110231" iyy="0.117188" izz="0.030159" ixy="-0.013234" iyz="7.3e-05" ixz="-5.6e-05"/>
  </inertial>
  <visual>
    <origin xyz="0.080858 0.165377 -0.8545" rpy="0 0 0"/>
    <geometry>
      <mesh filename="package://da_vincibot_description/meshes/forearm_1.stl" scale="0.001 0.001 0.001"/>
    </geometry>
    <material name="silver"/>
  </visual>
  <collision>
    <origin xyz="0.080858 0.165377 -0.8545" rpy="0 0 0"/>
    <geometry>
      <mesh filename="package://da_vincibot_description/meshes/forearm_1.stl" scale="0.001 0.001 0.001"/>
    </geometry>
  </collision>
</link>

<link name="hand_1">
  <inertial>
    <origin xyz="0.06847215720316376 -0.018647155150894656 0.05483920948448584" rpy="0 0 0"/>
    <mass value="1.0662125112424885"/>
    <inertia ixx="0.019715" iyy="0.016283" izz="0.016644" ixy="0.006528" iyz="0.00916" ixz="-0.007063"/>
  </inertial>
  <visual>
    <origin xyz="0.041263 0.134845 -1.2745" rpy="0 0 0"/>
    <geometry>
      <mesh filename="package://da_vincibot_description/meshes/hand_1.stl" scale="0.001 0.001 0.001"/>
    </geometry>
    <material name="silver"/>
  </visual>
  <collision>
    <origin xyz="0.041263 0.134845 -1.2745" rpy="0 0 0"/>
    <geometry>
      <mesh filename="package://da_vincibot_description/meshes/hand_1.stl" scale="0.001 0.001 0.001"/>
    </geometry>
  </collision>
</link>

<link name="hand_yaw_1">
  <inertial>
    <origin xyz="0.014374671356375074 -0.018641065652960254 0.019752517482224397" rpy="0 0 0"/>
    <mass value="0.19229044235074944"/>
    <inertia ixx="0.00039" iyy="0.000348" izz="0.000235" ixy="8.1e-05" iyz="-0.000115" ixz="8.9e-05"/>
  </inertial>
  <visual>
    <origin xyz="-0.175095 0.345273 -1.525187" rpy="0 0 0"/>
    <geometry>
      <mesh filename="package://da_vincibot_description/meshes/hand_yaw_1.stl" scale="0.001 0.001 0.001"/>
    </geometry>
    <material name="silver"/>
  </visual>
  <collision>
    <origin xyz="-0.175095 0.345273 -1.525187" rpy="0 0 0"/>
    <geometry>
      <mesh filename="package://da_vincibot_description/meshes/hand_yaw_1.stl" scale="0.001 0.001 0.001"/>
    </geometry>
  </collision>
</link>

<link name="end_effector_1">
  <inertial>
    <origin xyz="-0.13513566300895505 -0.08879838085005426 0.024916464751506773" rpy="0 0 0"/>
    <mass value="0.49047145154717503"/>
    <inertia ixx="0.000952" iyy="0.001273" izz="0.001944" ixy="-0.00082" iyz="2.2e-05" ixz="3.9e-05"/>
  </inertial>
  <visual>
    <origin xyz="-0.211088 0.391885 -1.541968" rpy="0 0 0"/>
    <geometry>
      <mesh filename="package://da_vincibot_description/meshes/end_effector_1.stl" scale="0.001 0.001 0.001"/>
    </geometry>
    <material name="silver"/>
  </visual>
  <collision>
    <origin xyz="-0.211088 0.391885 -1.541968" rpy="0 0 0"/>
    <geometry>
      <mesh filename="package://da_vincibot_description/meshes/end_effector_1.stl" scale="0.001 0.001 0.001"/>
    </geometry>
  </collision>
</link>

<link name="end_1">
  <inertial>
    <origin xyz="-3.878603250144497e-05 -3.171408265412179e-05 1.5213265980307256e-06" rpy="0 0 0"/>
    <mass value="0.00014967725498964528"/>
    <inertia ixx="0.0" iyy="0.0" izz="0.0" ixy="0.0" iyz="-0.0" ixz="-0.0"/>
  </inertial>
  <visual>
    <origin xyz="-0.016138 0.531822 -1.567211" rpy="0 0 0"/>
    <geometry>
      <mesh filename="package://da_vincibot_description/meshes/end_1.stl" scale="0.001 0.001 0.001"/>
    </geometry>
    <material name="silver"/>
  </visual>
  <collision>
    <origin xyz="-0.016138 0.531822 -1.567211" rpy="0 0 0"/>
    <geometry>
      <mesh filename="package://da_vincibot_description/meshes/end_1.stl" scale="0.001 0.001 0.001"/>
    </geometry>
  </collision>
</link>

<link name="arducam_v1_1">
  <inertial>
    <origin xyz="-0.020000131702510495 4.1679008455641764e-07 -0.0021523835366652477" rpy="0 0 0"/>
    <mass value="0.0047707963267949235"/>
    <inertia ixx="0.0" iyy="0.0" izz="1e-06" ixy="0.0" iyz="0.0" ixz="0.0"/>
  </inertial>
  <visual>
    <origin xyz="-0.010413 -0.339581 -1.41" rpy="0 0 0"/>
    <geometry>
      <mesh filename="package://da_vincibot_description/meshes/arducam_v1_1.stl" scale="0.001 0.001 0.001"/>
    </geometry>
    <material name="silver"/>
  </visual>
  <collision>
    <origin xyz="-0.010413 -0.339581 -1.41" rpy="0 0 0"/>
    <geometry>
      <mesh filename="package://da_vincibot_description/meshes/arducam_v1_1.stl" scale="0.001 0.001 0.001"/>
    </geometry>
  </collision>
</link>

<joint name="rigid2" type="fixed">
  <origin xyz="-0.019174 -0.220837 0.01" rpy="0 0 0"/>
  <parent link="base_link"/>
  <child link="foundation_base_1"/>
</joint>

<joint name="joint1_shoulder" type="revolute">
  <origin xyz="0.009587 0.110418 0.651" rpy="0 0 0"/>
  <parent link="foundation_base_1"/>
  <child link="shoulder_1"/>
  <axis xyz="0.0 -0.0 1.0"/>
  <limit upper="4.712389" lower="0.0" effort="100" velocity="100"/>
</joint>

<joint name="joint2_forearm" type="revolute">
  <origin xyz="-0.071271 -0.054958 0.1935" rpy="0 0 0"/>
  <parent link="shoulder_1"/>
  <child link="forearm_1"/>
  <axis xyz="0.7919 0.61065 0.0"/>
  <limit upper="2.094395" lower="0.0" effort="100" velocity="100"/>
</joint>

<joint name="joint3_hand" type="revolute">
  <origin xyz="0.039595 0.030532 0.42" rpy="0 0 0"/>
  <parent link="forearm_1"/>
  <child link="hand_1"/>
  <axis xyz="0.7919 0.61065 0.0"/>
  <limit upper="1.396263" lower="0.0" effort="100" velocity="100"/>
</joint>

<joint name="joint4_handyaw" type="revolute">
  <origin xyz="0.216358 -0.210428 0.250687" rpy="0 0 0"/>
  <parent link="hand_1"/>
  <child link="hand_yaw_1"/>
  <axis xyz="-0.467785 0.606631 -0.642788"/>
  <limit upper="3.141593" lower="0.0" effort="100" velocity="100"/>
</joint>

<joint name="joint5_end" type="revolute">
  <origin xyz="0.035993 -0.046612 0.016781" rpy="0 0 0"/>
  <parent link="hand_yaw_1"/>
  <child link="end_effector_1"/>
  <axis xyz="-0.393746 0.508076 0.766044"/>
  <limit upper="3.141593" lower="0.0" effort="100" velocity="100"/>
</joint>

<joint name="end_rigid" type="fixed">
  <origin xyz="-0.19495 -0.139937 0.025243" rpy="0 0 0"/>
  <parent link="end_effector_1"/>
  <child link="end_1"/>
</joint>

<joint name="rigid1" type="fixed">
  <origin xyz="0.010413 0.339581 1.41" rpy="0 0 0"/>
  <parent link="base_link"/>
  <child link="arducam_v1_1"/>
</joint>

</robot>
